Workbook
Name NativeTimeline_Fecha_Operación_REAL: #N/A
Name NativeTimeline_Fecha_valor_REAL: #N/A
Name Slicer_Cuenta: #N/A
Name Slicer_Tipo: #N/A

Sheet Sheet1
A2: Fecha valor REAL | B2: (All)
A4: Row Labels | B4: Average of Importe
A5: Alquiler | B5: -895.5
A6: Café | B6: -2.9951822
A7: Compras | B7: -23.4
A8: Deporte | B8: -3.645
A9: Deudas | B9: -58.793913
A10: Donación | B10: -30
A11: Entretenimiento | B11: -15.794573
A12: Establecernos | B12: -237.344
A13: Inversión | B13: -383.82353
A14: Master | B14: -627.91944
A15: Mercado | B15: -25.993321
A16: Navidad | B16: -70.83814
... A26: Grand Total | B26: -38.41223
N53: Average of Saldo | O53: Column Labels
N54: Row Labels | O54: Cristina | P54: Cuentas | Q54: Nomina | R54: Grand Total
N55: 2023 | O55: 2940.0624 | P55: 491.05949 | Q55: 643.44028 | R55: 1216.832
N56: Qtr2 | O56: 1775.4392 | P56: 975.7725 | R56: 1587.2824
N57: Jun | O57: 1775.4392 | P57: 975.7725 | R57: 1587.2824
N58: 45090 | O58: 3000 | R58: 3000
N59: 45091 | O59: 2489.23 | R59: 2489.23
N60: 45092 | O60: 2218.93 | R60: 2218.93
N61: 45096 | O61: 1586.53 | R61: 1586.53
N62: 45098 | O62: 955.28 | R62: 955.28
N63: 45101 | O63: 950.78 | R63: 950.78
N64: 45103 | O64: 947.38 | R64: 947.38
N65: 45104 | O65: 942.38 | P65: 5 | R65: 473.69
N66: 45105 | O66: 935.98 | P66: 1301.52 | R66: 1179.6733
N67: 45106 | P67: 1295.05 | R67: 1295.05
N68: Qtr3 | O68: 2278.7012 | P68: 284.1416 | Q68: 894.39 | R68: 985.36382
N69: Jul | O69: 1986.205 | P69: 681.348 | R69: 1702.5404
N70: 45108 | O70: 932.98 | R70: 932.98
N71: 45110 | P71: 395.05 | R71: 395.05
N72: 45112 | O72: 2182.6967 | R72: 2182.6967
N73: 45113 | O73: 2176.575 | R73: 2176.575
N74: 45114 | O74: 2147.81 | R74: 2147.81
N75: 45115 | O75: 2121.92 | R75: 2121.92
N76: 45118 | O76: 2113.81 | R76: 2113.81
N77: 45119 | O77: 2098.465 | R77: 2098.465
...

Sheet Análisis del presupuesto
B1: Total gastado
B2: Jan | C2: Feb | D2: Mar | E2: Apr | F2: May | G2: Jun | H2: Jul | I2: Aug | J2: Sep | K2: Oct | L2: Nov | M2: Dec
A3: Aporte a la casa | B3: =SUMIFS(Data!$I:$I, Data!$F:$F, $B59, Data!$C:$C, ">=" & DATE(2025, MATCH(C$56, {"Jan","Feb","Mar","Apr","May","Jun","Jul","Aug","Sep","Oct","Nov","Dec"}, 0), 1), Data!C:C, "<" & EDATE(DATE(2025, MATCH(C$56, {"Jan","Feb","Mar","Apr","May","Jun","Jul","Aug","Sep","Oct","Nov","Dec"}, 0), 1), 1)) -> 200 | C3: =SUMIFS(Data!$I:$I, Data!$F:$F, $B59, Data!$C:$C, ">=" & DATE(2025, MATCH(D$56, {"Jan","Feb","Mar","Apr","May","Jun","Jul","Aug","Sep","Oct","Nov","Dec"}, 0), 1), Data!D:D, "<" & EDATE(DATE(2025, MATCH(D$56, {"Jan","Feb","Mar","Apr","May","Jun","Jul","Aug","Sep","Oct","Nov","Dec"}, 0), 1), 1)) -> 600 | D3: =SUMIFS(Data!$I:$I, Data!$F:$F, $B59, Data!$C:$C, ">=" & DATE(2025, MATCH(E$56, {"Jan","Feb","Mar","Apr","May","Jun","Jul","Aug","Sep","Oct","Nov","Dec"}, 0), 1), Data!E:E, "<" & EDATE(DATE(2025, MATCH(E$56, {"Jan","Feb","Mar","Apr","May","Jun","Jul","Aug","Sep","Oct","Nov","Dec"}, 0), 1), 1)) -> 0 | E3: =SUMIFS(Data!$I:$I, Data!$F:$F, $B59, Data!$C:$C, ">=" & DATE(2025, MATCH(F$56, {"Jan","Feb","Mar","Apr","May","Jun","Jul","Aug","Sep","Oct","Nov","Dec"}, 0), 1), Data!F:F, "<" & EDATE(DATE(2025, MATCH(F$56, {"Jan","Feb","Mar","Apr","May","Jun","Jul","Aug","Sep","Oct","Nov","Dec"}, 0), 1), 1)) -> 0 | F3: =SUMIFS(Data!$I:$I, Data!$F:$F, $B59, Data!$C:$C, ">=" & DATE(2025, MATCH(G$56, {"Jan","Feb","Mar","Apr","May","Jun","Jul","Aug","Sep","Oct","Nov","Dec"}, 0), 1), Data!G:G, "<" & EDATE(DATE(2025, MATCH(G$56, {"Jan","Feb","Mar","Apr","May","Jun","Jul","Aug","Sep","Oct","Nov","Dec"}, 0), 1), 1)) -> 0 | G3: =SUMIFS(Data!$I:$I, Data!$F:$F, $B59, Data!$C:$C, ">=" & DATE(2025, MATCH(H$56, {"Jan","Feb","Mar","Apr","May","Jun","Jul","Aug","Sep","Oct","Nov","Dec"}, 0), 1), Data!H:H, "<" & EDATE(DATE(2025, MATCH(H$56, {"Jan","Feb","Mar","Apr","May","Jun","Jul","Aug","Sep","Oct","Nov","Dec"}, 0), 1), 1)) -> 0 | H3: =SUMIFS(Data!$I:$I, Data!$F:$F, $B59, Data!$C:$C, ">=" & DATE(2025, MATCH(I$56, {"Jan","Feb","Mar","Apr","May","Jun","Jul","Aug","Sep","Oct","Nov","Dec"}, 0), 1), Data!I:I, "<" & EDATE(DATE(2025, MATCH(I$56, {"Jan","Feb","Mar","Apr","May","Jun","Jul","Aug","Sep","Oct","Nov","Dec"}, 0), 1), 1)) -> 1416 | I3: =SUMIFS(Data!$I:$I, Data!$F:$F, $B59, Data!$C:$C, ">=" & DATE(2025, MATCH(J$56, {"Jan","Feb","Mar","Apr","May","Jun","Jul","Aug","Sep","Oct","Nov","Dec"}, 0), 1), Data!J:J, "<" & EDATE(DATE(2025, MATCH(J$56, {"Jan","Feb","Mar","Apr","May","Jun","Jul","Aug","Sep","Oct","Nov","Dec"}, 0), 1), 1)) -> 0 | J3: =SUMIFS(Data!$I:$I, Data!$F:$F, $B59, Data!$C:$C, ">=" & DATE(2025, MATCH(K$56, {"Jan","Feb","Mar","Apr","May","Jun","Jul","Aug","Sep","Oct","Nov","Dec"}, 0), 1), Data!K:K, "<" & EDATE(DATE(2025, MATCH(K$56, {"Jan","Feb","Mar","Apr","May","Jun","Jul","Aug","Sep","Oct","Nov","Dec"}, 0), 1), 1)) -> 1400 | K3: =SUMIFS(Data!$I:$I, Data!$F:$F, $B59, Data!$C:$C, ">=" & DATE(2025, MATCH(L$56, {"Jan","Feb","Mar","Apr","May","Jun","Jul","Aug","Sep","Oct","Nov","Dec"}, 0), 1), Data!L:L, "<" & EDATE(DATE(2025, MATCH(L$56, {"Jan","Feb","Mar","Apr","May","Jun","Jul","Aug","Sep","Oct","Nov","Dec"}, 0), 1), 1)) -> 0 | L3: =SUMIFS(Data!$I:$I, Data!$F:$F, $B59, Data!$C:$C, ">=" & DATE(2025, MATCH(M$56, {"Jan","Feb","Mar","Apr","May","Jun","Jul","Aug","Sep","Oct","Nov","Dec"}, 0), 1), Data!M:M, "<" & EDATE(DATE(2025, MATCH(M$56, {"Jan","Feb","Mar","Apr","May","Jun","Jul","Aug","Sep","Oct","Nov","Dec"}, 0), 1), 1)) -> 0 | M3: =SUMIFS(Data!$I:$I, Data!$F:$F, $B59, Data!$C:$C, ">=" & DATE(2025, MATCH(N$56, {"Jan","Feb","Mar","Apr","May","Jun","Jul","Aug","Sep","Oct","Nov","Dec"}, 0), 1), Data!N:N, "<" & EDATE(DATE(2025, MATCH(N$56, {"Jan","Feb","Mar","Apr","May","Jun","Jul","Aug","Sep","Oct","Nov","Dec"}, 0), 1), 1)) -> 0
A4: Sueldo | B4: =SUMIFS(Data!I:I, Data!F:F, $B60, Data!C:C, ">=" & DATE(2025, MATCH(C$56, {"Jan","Feb","Mar","Apr","May","Jun","Jul","Aug","Sep","Oct","Nov","Dec"}, 0), 1), Data!C:C, "<" & EDATE(DATE(2025, MATCH(C$56, {"Jan","Feb","Mar","Apr","May","Jun","Jul","Aug","Sep","Oct","Nov","Dec"}, 0), 1), 1)) -> 4529.03 | C4: =SUMIFS(Data!$I:$I, Data!$F:$F, $B60, Data!$C:$C, ">=" & DATE(2025, MATCH(D$56, {"Jan","Feb","Mar","Apr","May","Jun","Jul","Aug","Sep","Oct","Nov","Dec"}, 0), 1), Data!D:D, "<" & EDATE(DATE(2025, MATCH(D$56, {"Jan","Feb","Mar","Apr","May","Jun","Jul","Aug","Sep","Oct","Nov","Dec"}, 0), 1), 1)) -> 15788.77 | D4: =SUMIFS(Data!$I:$I, Data!$F:$F, $B60, Data!$C:$C, ">=" & DATE(2025, MATCH(E$56, {"Jan","Feb","Mar","Apr","May","Jun","Jul","Aug","Sep","Oct","Nov","Dec"}, 0), 1), Data!E:E, "<" & EDATE(DATE(2025, MATCH(E$56, {"Jan","Feb","Mar","Apr","May","Jun","Jul","Aug","Sep","Oct","Nov","Dec"}, 0), 1), 1)) -> 10082.66 | E4: =SUMIFS(Data!$I:$I, Data!$F:$F, $B60, Data!$C:$C, ">=" & DATE(2025, MATCH(F$56, {"Jan","Feb","Mar","Apr","May","Jun","Jul","Aug","Sep","Oct","Nov","Dec"}, 0), 1), Data!F:F, "<" & EDATE(DATE(2025, MATCH(F$56, {"Jan","Feb","Mar","Apr","May","Jun","Jul","Aug","Sep","Oct","Nov","Dec"}, 0), 1), 1)) -> 0 | F4: =SUMIFS(Data!$I:$I, Data!$F:$F, $B60, Data!$C:$C, ">=" & DATE(2025, MATCH(G$56, {"Jan","Feb","Mar","Apr","May","Jun","Jul","Aug","Sep","Oct","Nov","Dec"}, 0), 1), Data!G:G, "<" & EDATE(DATE(2025, MATCH(G$56, {"Jan","Feb","Mar","Apr","May","Jun","Jul","Aug","Sep","Oct","Nov","Dec"}, 0), 1), 1)) -> 0 | G4: =SUMIFS(Data!$I:$I, Data!$F:$F, $B60, Data!$C:$C, ">=" & DATE(2025, MATCH(H$56, {"Jan","Feb","Mar","Apr","May","Jun","Jul","Aug","Sep","Oct","Nov","Dec"}, 0), 1), Data!H:H, "<" & EDATE(DATE(2025, MATCH(H$56, {"Jan","Feb","Mar","Apr","May","Jun","Jul","Aug","Sep","Oct","Nov","Dec"}, 0), 1), 1)) -> 0 | H4: =SUMIFS(Data!$I:$I, Data!$F:$F, $B60, Data!$C:$C, ">=" & DATE(2025, MATCH(I$56, {"Jan","Feb","Mar","Apr","May","Jun","Jul","Aug","Sep","Oct","Nov","Dec"}, 0), 1), Data!I:I, "<" & EDATE(DATE(2025, MATCH(I$56, {"Jan","Feb","Mar","Apr","May","Jun","Jul","Aug","Sep","Oct","Nov","Dec"}, 0), 1), 1)) -> 36625.58 | I4: =SUMIFS(Data!$I:$I, Data!$F:$F, $B60, Data!$C:$C, ">=" & DATE(2025, MATCH(J$56, {"Jan","Feb","Mar","Apr","May","Jun","Jul","Aug","Sep","Oct","Nov","Dec"}, 0), 1), Data!J:J, "<" & EDATE(DATE(2025, MATCH(J$56, {"Jan","Feb","Mar","Apr","May","Jun","Jul","Aug","Sep","Oct","Nov","Dec"}, 0), 1), 1)) -> 0 | J4: =SUMIFS(Data!$I:$I, Data!$F:$F, $B60, Data!$C:$C, ">=" & DATE(2025, MATCH(K$56, {"Jan","Feb","Mar","Apr","May","Jun","Jul","Aug","Sep","Oct","Nov","Dec"}, 0), 1), Data!K:K, "<" & EDATE(DATE(2025, MATCH(K$56, {"Jan","Feb","Mar","Apr","May","Jun","Jul","Aug","Sep","Oct","Nov","Dec"}, 0), 1), 1)) -> 34421.45 | K4: =SUMIFS(Data!$I:$I, Data!$F:$F, $B60, Data!$C:$C, ">=" & DATE(2025, MATCH(L$56, {"Jan","Feb","Mar","Apr","May","Jun","Jul","Aug","Sep","Oct","Nov","Dec"}, 0), 1), Data!L:L, "<" & EDATE(DATE(2025, MATCH(L$56, {"Jan","Feb","Mar","Apr","May","Jun","Jul","Aug","Sep","Oct","Nov","Dec"}, 0), 1), 1)) -> 0 | L4: =SUMIFS(Data!$I:$I, Data!$F:$F, $B60, Data!$C:$C, ">=" & DATE(2025, MATCH(M$56, {"Jan","Feb","Mar","Apr","May","Jun","Jul","Aug","Sep","Oct","Nov","Dec"}, 0), 1), Data!M:M, "<" & EDATE(DATE(2025, MATCH(M$56, {"Jan","Feb","Mar","Apr","May","Jun","Jul","Aug","Sep","Oct","Nov","Dec"}, 0), 1), 1)) -> 0 | M4: =SUMIFS(Data!$I:$I, Data!$F:$F, $B60, Data!$C:$C, ">=" & DATE(2025, MATCH(N$56, {"Jan","Feb","Mar","Apr","May","Jun","Jul","Aug","Sep","Oct","Nov","Dec"}, 0), 1), Data!N:N, "<" & EDATE(DATE(2025, MATCH(N$56, {"Jan","Feb","Mar","Apr","May","Jun","Jul","Aug","Sep","Oct","Nov","Dec"}, 0), 1), 1)) -> 0
B5: =SUMIFS(Data!I:I, Data!F:F, $B61, Data!C:C, ">=" & DATE(2025, MATCH(C$56, {"Jan","Feb","Mar","Apr","May","Jun","Jul","Aug","Sep","Oct","Nov","Dec"}, 0), 1), Data!C:C, "<" & EDATE(DATE(2025, MATCH(C$56, {"Jan","Feb","Mar","Apr","May","Jun","Jul","Aug","Sep","Oct","Nov","Dec"}, 0), 1), 1)) -> 0 | C5: =SUMIFS(Data!$I:$I, Data!$F:$F, $B61, Data!$C:$C, ">=" & DATE(2025, MATCH(D$56, {"Jan","Feb","Mar","Apr","May","Jun","Jul","Aug","Sep","Oct","Nov","Dec"}, 0), 1), Data!D:D, "<" & EDATE(DATE(2025, MATCH(D$56, {"Jan","Feb","Mar","Apr","May","Jun","Jul","Aug","Sep","Oct","Nov","Dec"}, 0), 1), 1)) -> 0 | D5: =SUMIFS(Data!$I:$I, Data!$F:$F, $B61, Data!$C:$C, ">=" & DATE(2025, MATCH(E$56, {"Jan","Feb","Mar","Apr","May","Jun","Jul","Aug","Sep","Oct","Nov","Dec"}, 0), 1), Data!E:E, "<" & EDATE(DATE(2025, MATCH(E$56, {"Jan","Feb","Mar","Apr","May","Jun","Jul","Aug","Sep","Oct","Nov","Dec"}, 0), 1), 1)) -> 0 | E5: =SUMIFS(Data!$I:$I, Data!$F:$F, $B61, Data!$C:$C, ">=" & DATE(2025, MATCH(F$56, {"Jan","Feb","Mar","Apr","May","Jun","Jul","Aug","Sep","Oct","Nov","Dec"}, 0), 1), Data!F:F, "<" & EDATE(DATE(2025, MATCH(F$56, {"Jan","Feb","Mar","Apr","May","Jun","Jul","Aug","Sep","Oct","Nov","Dec"}, 0), 1), 1)) -> 0 | F5: =SUMIFS(Data!$I:$I, Data!$F:$F, $B61, Data!$C:$C, ">=" & DATE(2025, MATCH(G$56, {"Jan","Feb","Mar","Apr","May","Jun","Jul","Aug","Sep","Oct","Nov","Dec"}, 0), 1), Data!G:G, "<" & EDATE(DATE(2025, MATCH(G$56, {"Jan","Feb","Mar","Apr","May","Jun","Jul","Aug","Sep","Oct","Nov","Dec"}, 0), 1), 1)) -> 0 | G5: =SUMIFS(Data!$I:$I, Data!$F:$F, $B61, Data!$C:$C, ">=" & DATE(2025, MATCH(H$56, {"Jan","Feb","Mar","Apr","May","Jun","Jul","Aug","Sep","Oct","Nov","Dec"}, 0), 1), Data!H:H, "<" & EDATE(DATE(2025, MATCH(H$56, {"Jan","Feb","Mar","Apr","May","Jun","Jul","Aug","Sep","Oct","Nov","Dec"}, 0), 1), 1)) -> 0 | H5: =SUMIFS(Data!$I:$I, Data!$F:$F, $B61, Data!$C:$C, ">=" & DATE(2025, MATCH(I$56, {"Jan","Feb","Mar","Apr","May","Jun","Jul","Aug","Sep","Oct","Nov","Dec"}, 0), 1), Data!I:I, "<" & EDATE(DATE(2025, MATCH(I$56, {"Jan","Feb","Mar","Apr","May","Jun","Jul","Aug","Sep","Oct","Nov","Dec"}, 0), 1), 1)) -> 0 | I5: =SUMIFS(Data!$I:$I, Data!$F:$F, $B61, Data!$C:$C, ">=" & DATE(2025, MATCH(J$56, {"Jan","Feb","Mar","Apr","May","Jun","Jul","Aug","Sep","Oct","Nov","Dec"}, 0), 1), Data!J:J, "<" & EDATE(DATE(2025, MATCH(J$56, {"Jan","Feb","Mar","Apr","May","Jun","Jul","Aug","Sep","Oct","Nov","Dec"}, 0), 1), 1)) -> 0 | J5: =SUMIFS(Data!$I:$I, Data!$F:$F, $B61, Data!$C:$C, ">=" & DATE(2025, MATCH(K$56, {"Jan","Feb","Mar","Apr","May","Jun","Jul","Aug","Sep","Oct","Nov","Dec"}, 0), 1), Data!K:K, "<" & EDATE(DATE(2025, MATCH(K$56, {"Jan","Feb","Mar","Apr","May","Jun","Jul","Aug","Sep","Oct","Nov","Dec"}, 0), 1), 1)) -> 0 | K5: =SUMIFS(Data!$I:$I, Data!$F:$F, $B61, Data!$C:$C, ">=" & DATE(2025, MATCH(L$56, {"Jan","Feb","Mar","Apr","May","Jun","Jul","Aug","Sep","Oct","Nov","Dec"}, 0), 1), Data!L:L, "<" & EDATE(DATE(2025, MATCH(L$56, {"Jan","Feb","Mar","Apr","May","Jun","Jul","Aug","Sep","Oct","Nov","Dec"}, 0), 1), 1)) -> 0 | L5: =SUMIFS(Data!$I:$I, Data!$F:$F, $B61, Data!$C:$C, ">=" & DATE(2025, MATCH(M$56, {"Jan","Feb","Mar","Apr","May","Jun","Jul","Aug","Sep","Oct","Nov","Dec"}, 0), 1), Data!M:M, "<" & EDATE(DATE(2025, MATCH(M$56, {"Jan","Feb","Mar","Apr","May","Jun","Jul","Aug","Sep","Oct","Nov","Dec"}, 0), 1), 1)) -> 0 | M5: =SUMIFS(Data!$I:$I, Data!$F:$F, $B61, Data!$C:$C, ">=" & DATE(2025, MATCH(N$56, {"Jan","Feb","Mar","Apr","May","Jun","Jul","Aug","Sep","Oct","Nov","Dec"}, 0), 1), Data!N:N, "<" & EDATE(DATE(2025, MATCH(N$56, {"Jan","Feb","Mar","Apr","May","Jun","Jul","Aug","Sep","Oct","Nov","Dec"}, 0), 1), 1)) -> 0
A6: Alquiler | B6: =SUMIFS(Data!I:I, Data!F:F, $B62, Data!C:C, ">=" & DATE(2025, MATCH(C$56, {"Jan","Feb","Mar","Apr","May","Jun","Jul","Aug","Sep","Oct","Nov","Dec"}, 0), 1), Data!C:C, "<" & EDATE(DATE(2025, MATCH(C$56, {"Jan","Feb","Mar","Apr","May","Jun","Jul","Aug","Sep","Oct","Nov","Dec"}, 0), 1), 1)) -> 0 | C6: =SUMIFS(Data!$I:$I, Data!$F:$F, $B62, Data!$C:$C, ">=" & DATE(2025, MATCH(D$56, {"Jan","Feb","Mar","Apr","May","Jun","Jul","Aug","Sep","Oct","Nov","Dec"}, 0), 1), Data!D:D, "<" & EDATE(DATE(2025, MATCH(D$56, {"Jan","Feb","Mar","Apr","May","Jun","Jul","Aug","Sep","Oct","Nov","Dec"}, 0), 1), 1)) -> -1872 | D6: =SUMIFS(Data!$I:$I, Data!$F:$F, $B62, Data!$C:$C, ">=" & DATE(2025, MATCH(E$56, {"Jan","Feb","Mar","Apr","May","Jun","Jul","Aug","Sep","Oct","Nov","Dec"}, 0), 1), Data!E:E, "<" & EDATE(DATE(2025, MATCH(E$56, {"Jan","Feb","Mar","Apr","May","Jun","Jul","Aug","Sep","Oct","Nov","Dec"}, 0), 1), 1)) -> -1836 | E6: =SUMIFS(Data!$I:$I, Data!$F:$F, $B62, Data!$C:$C, ">=" & DATE(2025, MATCH(F$56, {"Jan","Feb","Mar","Apr","May","Jun","Jul","Aug","Sep","Oct","Nov","Dec"}, 0), 1), Data!F:F, "<" & EDATE(DATE(2025, MATCH(F$56, {"Jan","Feb","Mar","Apr","May","Jun","Jul","Aug","Sep","Oct","Nov","Dec"}, 0), 1), 1)) -> 0 | F6: =SUMIFS(Data!$I:$I, Data!$F:$F, $B62, Data!$C:$C, ">=" & DATE(2025, MATCH(G$56, {"Jan","Feb","Mar","Apr","May","Jun","Jul","Aug","Sep","Oct","Nov","Dec"}, 0), 1), Data!G:G, "<" & EDATE(DATE(2025, MATCH(G$56, {"Jan","Feb","Mar","Apr","May","Jun","Jul","Aug","Sep","Oct","Nov","Dec"}, 0), 1), 1)) -> 0 | G6: =SUMIFS(Data!$I:$I, Data!$F:$F, $B62, Data!$C:$C, ">=" & DATE(2025, MATCH(H$56, {"Jan","Feb","Mar","Apr","May","Jun","Jul","Aug","Sep","Oct","Nov","Dec"}, 0), 1), Data!H:H, "<" & EDATE(DATE(2025, MATCH(H$56, {"Jan","Feb","Mar","Apr","May","Jun","Jul","Aug","Sep","Oct","Nov","Dec"}, 0), 1), 1)) -> 0 | H6: =SUMIFS(Data!$I:$I, Data!$F:$F, $B62, Data!$C:$C, ">=" & DATE(2025, MATCH(I$56, {"Jan","Feb","Mar","Apr","May","Jun","Jul","Aug","Sep","Oct","Nov","Dec"}, 0), 1), Data!I:I, "<" & EDATE(DATE(2025, MATCH(I$56, {"Jan","Feb","Mar","Apr","May","Jun","Jul","Aug","Sep","Oct","Nov","Dec"}, 0), 1), 1)) -> -9895 | I6: =SUMIFS(Data!$I:$I, Data!$F:$F, $B62, Data!$C:$C, ">=" & DATE(2025, MATCH(J$56, {"Jan","Feb","Mar","Apr","May","Jun","Jul","Aug","Sep","Oct","Nov","Dec"}, 0), 1), Data!J:J, "<" & EDATE(DATE(2025, MATCH(J$56, {"Jan","Feb","Mar","Apr","May","Jun","Jul","Aug","Sep","Oct","Nov","Dec"}, 0), 1), 1)) -> 0 | J6: =SUMIFS(Data!$I:$I, Data!$F:$F, $B62, Data!$C:$C, ">=" & DATE(2025, MATCH(K$56, {"Jan","Feb","Mar","Apr","May","Jun","Jul","Aug","Sep","Oct","Nov","Dec"}, 0), 1), Data!K:K, "<" & EDATE(DATE(2025, MATCH(K$56, {"Jan","Feb","Mar","Apr","May","Jun","Jul","Aug","Sep","Oct","Nov","Dec"}, 0), 1), 1)) -> -8041 | K6: =SUMIFS(Data!$I:$I, Data!$F:$F, $B62, Data!$C:$C, ">=" & DATE(2025, MATCH(L$56, {"Jan","Feb","Mar","Apr","May","Jun","Jul","Aug","Sep","Oct","Nov","Dec"}, 0), 1), Data!L:L, "<" & EDATE(DATE(2025, MATCH(L$56, {"Jan","Feb","Mar","Apr","May","Jun","Jul","Aug","Sep","Oct","Nov","Dec"}, 0), 1), 1)) -> 0 | L6: =SUMIFS(Data!$I:$I, Data!$F:$F, $B62, Data!$C:$C, ">=" & DATE(2025, MATCH(M$56, {"Jan","Feb","Mar","Apr","May","Jun","Jul","Aug","Sep","Oct","Nov","Dec"}, 0), 1), Data!M:M, "<" & EDATE(DATE(2025, MATCH(M$56, {"Jan","Feb","Mar","Apr","May","Jun","Jul","Aug","Sep","Oct","Nov","Dec"}, 0), 1), 1)) -> 0 | M6: =SUMIFS(Data!$I:$I, Data!$F:$F, $B62, Data!$C:$C, ">=" & DATE(2025, MATCH(N$56, {"Jan","Feb","Mar","Apr","May","Jun","Jul","Aug","Sep","Oct","Nov","Dec"}, 0), 1), Data!N:N, "<" & EDATE(DATE(2025, MATCH(N$56, {"Jan","Feb","Mar","Apr","May","Jun","Jul","Aug","Sep","Oct","Nov","Dec"}, 0), 1), 1)) -> 0
A7: ayes | B7: =SUMIFS(Data!I:I, Data!F:F, $B63, Data!C:C, ">=" & DATE(2025, MATCH(C$56, {"Jan","Feb","Mar","Apr","May","Jun","Jul","Aug","Sep","Oct","Nov","Dec"}, 0), 1), Data!C:C, "<" & EDATE(DATE(2025, MATCH(C$56, {"Jan","Feb","Mar","Apr","May","Jun","Jul","Aug","Sep","Oct","Nov","Dec"}, 0), 1), 1)) -> 0 | C7: =SUMIFS(Data!$I:$I, Data!$F:$F, $B63, Data!$C:$C, ">=" & DATE(2025, MATCH(D$56, {"Jan","Feb","Mar","Apr","May","Jun","Jul","Aug","Sep","Oct","Nov","Dec"}, 0), 1), Data!D:D, "<" & EDATE(DATE(2025, MATCH(D$56, {"Jan","Feb","Mar","Apr","May","Jun","Jul","Aug","Sep","Oct","Nov","Dec"}, 0), 1), 1)) -> 0 | D7: =SUMIFS(Data!$I:$I, Data!$F:$F, $B63, Data!$C:$C, ">=" & DATE(2025, MATCH(E$56, {"Jan","Feb","Mar","Apr","May","Jun","Jul","Aug","Sep","Oct","Nov","Dec"}, 0), 1), Data!E:E, "<" & EDATE(DATE(2025, MATCH(E$56, {"Jan","Feb","Mar","Apr","May","Jun","Jul","Aug","Sep","Oct","Nov","Dec"}, 0), 1), 1)) -> 0 | E7: =SUMIFS(Data!$I:$I, Data!$F:$F, $B63, Data!$C:$C, ">=" & DATE(2025, MATCH(F$56, {"Jan","Feb","Mar","Apr","May","Jun","Jul","Aug","Sep","Oct","Nov","Dec"}, 0), 1), Data!F:F, "<" & EDATE(DATE(2025, MATCH(F$56, {"Jan","Feb","Mar","Apr","May","Jun","Jul","Aug","Sep","Oct","Nov","Dec"}, 0), 1), 1)) -> 0 | F7: =SUMIFS(Data!$I:$I, Data!$F:$F, $B63, Data!$C:$C, ">=" & DATE(2025, MATCH(G$56, {"Jan","Feb","Mar","Apr","May","Jun","Jul","Aug","Sep","Oct","Nov","Dec"}, 0), 1), Data!G:G, "<" & EDATE(DATE(2025, MATCH(G$56, {"Jan","Feb","Mar","Apr","May","Jun","Jul","Aug","Sep","Oct","Nov","Dec"}, 0), 1), 1)) -> 0 | G7: =SUMIFS(Data!$I:$I, Data!$F:$F, $B63, Data!$C:$C, ">=" & DATE(2025, MATCH(H$56, {"Jan","Feb","Mar","Apr","May","Jun","Jul","Aug","Sep","Oct","Nov","Dec"}, 0), 1), Data!H:H, "<" & EDATE(DATE(2025, MATCH(H$56, {"Jan","Feb","Mar","Apr","May","Jun","Jul","Aug","Sep","Oct","Nov","Dec"}, 0), 1), 1)) -> 0 | H7: =SUMIFS(Data!$I:$I, Data!$F:$F, $B63, Data!$C:$C, ">=" & DATE(2025, MATCH(I$56, {"Jan","Feb","Mar","Apr","May","Jun","Jul","Aug","Sep","Oct","Nov","Dec"}, 0), 1), Data!I:I, "<" & EDATE(DATE(2025, MATCH(I$56, {"Jan","Feb","Mar","Apr","May","Jun","Jul","Aug","Sep","Oct","Nov","Dec"}, 0), 1), 1)) -> 0 | I7: =SUMIFS(Data!$I:$I, Data!$F:$F, $B63, Data!$C:$C, ">=" & DATE(2025, MATCH(J$56, {"Jan","Feb","Mar","Apr","May","Jun","Jul","Aug","Sep","Oct","Nov","Dec"}, 0), 1), Data!J:J, "<" & EDATE(DATE(2025, MATCH(J$56, {"Jan","Feb","Mar","Apr","May","Jun","Jul","Aug","Sep","Oct","Nov","Dec"}, 0), 1), 1)) -> 0 | J7: =SUMIFS(Data!$I:$I, Data!$F:$F, $B63, Data!$C:$C, ">=" & DATE(2025, MATCH(K$56, {"Jan","Feb","Mar","Apr","May","Jun","Jul","Aug","Sep","Oct","Nov","Dec"}, 0), 1), Data!K:K, "<" & EDATE(DATE(2025, MATCH(K$56, {"Jan","Feb","Mar","Apr","May","Jun","Jul","Aug","Sep","Oct","Nov","Dec"}, 0), 1), 1)) -> 0 | K7: =SUMIFS(Data!$I:$I, Data!$F:$F, $B63, Data!$C:$C, ">=" & DATE(2025, MATCH(L$56, {"Jan","Feb","Mar","Apr","May","Jun","Jul","Aug","Sep","Oct","Nov","Dec"}, 0), 1), Data!L:L, "<" & EDATE(DATE(2025, MATCH(L$56, {"Jan","Feb","Mar","Apr","May","Jun","Jul","Aug","Sep","Oct","Nov","Dec"}, 0), 1), 1)) -> 0 | L7: =SUMIFS(Data!$I:$I, Data!$F:$F, $B63, Data!$C:$C, ">=" & DATE(2025, MATCH(M$56, {"Jan","Feb","Mar","Apr","May","Jun","Jul","Aug","Sep","Oct","Nov","Dec"}, 0), 1), Data!M:M, "<" & EDATE(DATE(2025, MATCH(M$56, {"Jan","Feb","Mar","Apr","May","Jun","Jul","Aug","Sep","Oct","Nov","Dec"}, 0), 1), 1)) -> 0 | M7: =SUMIFS(Data!$I:$I, Data!$F:$F, $B63, Data!$C:$C, ">=" & DATE(2025, MATCH(N$56, {"Jan","Feb","Mar","Apr","May","Jun","Jul","Aug","Sep","Oct","Nov","Dec"}, 0), 1), Data!N:N, "<" & EDATE(DATE(2025, MATCH(N$56, {"Jan","Feb","Mar","Apr","May","Jun","Jul","Aug","Sep","Oct","Nov","Dec"}, 0), 1), 1)) -> 0
A8: café | B8: =SUMIFS(Data!I:I, Data!F:F, $B64, Data!C:C, ">=" & DATE(2025, MATCH(C$56, {"Jan","Feb","Mar","Apr","May","Jun","Jul","Aug","Sep","Oct","Nov","Dec"}, 0), 1), Data!C:C, "<" & EDATE(DATE(2025, MATCH(C$56, {"Jan","Feb","Mar","Apr","May","Jun","Jul","Aug","Sep","Oct","Nov","Dec"}, 0), 1), 1)) -> -33.2 | C8: =SUMIFS(Data!$I:$I, Data!$F:$F, $B64, Data!$C:$C, ">=" & DATE(2025, MATCH(D$56, {"Jan","Feb","Mar","Apr","May","Jun","Jul","Aug","Sep","Oct","Nov","Dec"}, 0), 1), Data!D:D, "<" & EDATE(DATE(2025, MATCH(D$56, {"Jan","Feb","Mar","Apr","May","Jun","Jul","Aug","Sep","Oct","Nov","Dec"}, 0), 1), 1)) -> -18.29 | D8: =SUMIFS(Data!$I:$I, Data!$F:$F, $B64, Data!$C:$C, ">=" & DATE(2025, MATCH(E$56, {"Jan","Feb","Mar","Apr","May","Jun","Jul","Aug","Sep","Oct","Nov","Dec"}, 0), 1), Data!E:E, "<" & EDATE(DATE(2025, MATCH(E$56, {"Jan","Feb","Mar","Apr","May","Jun","Jul","Aug","Sep","Oct","Nov","Dec"}, 0), 1), 1)) -> 0 | E8: =SUMIFS(Data!$I:$I, Data!$F:$F, $B64, Data!$C:$C, ">=" & DATE(2025, MATCH(F$56, {"Jan","Feb","Mar","Apr","May","Jun","Jul","Aug","Sep","Oct","Nov","Dec"}, 0), 1), Data!F:F, "<" & EDATE(DATE(2025, MATCH(F$56, {"Jan","Feb","Mar","Apr","May","Jun","Jul","Aug","Sep","Oct","Nov","Dec"}, 0), 1), 1)) -> 0 | F8: =SUMIFS(Data!$I:$I, Data!$F:$F, $B64, Data!$C:$C, ">=" & DATE(2025, MATCH(G$56, {"Jan","Feb","Mar","Apr","May","Jun","Jul","Aug","Sep","Oct","Nov","Dec"}, 0), 1), Data!G:G, "<" & EDATE(DATE(2025, MATCH(G$56, {"Jan","Feb","Mar","Apr","May","Jun","Jul","Aug","Sep","Oct","Nov","Dec"}, 0), 1), 1)) -> 0 | G8: =SUMIFS(Data!$I:$I, Data!$F:$F, $B64, Data!$C:$C, ">=" & DATE(2025, MATCH(H$56, {"Jan","Feb","Mar","Apr","May","Jun","Jul","Aug","Sep","Oct","Nov","Dec"}, 0), 1), Data!H:H, "<" & EDATE(DATE(2025, MATCH(H$56, {"Jan","Feb","Mar","Apr","May","Jun","Jul","Aug","Sep","Oct","Nov","Dec"}, 0), 1), 1)) -> 0 | H8: =SUMIFS(Data!$I:$I, Data!$F:$F, $B64, Data!$C:$C, ">=" & DATE(2025, MATCH(I$56, {"Jan","Feb","Mar","Apr","May","Jun","Jul","Aug","Sep","Oct","Nov","Dec"}, 0), 1), Data!I:I, "<" & EDATE(DATE(2025, MATCH(I$56, {"Jan","Feb","Mar","Apr","May","Jun","Jul","Aug","Sep","Oct","Nov","Dec"}, 0), 1), 1)) -> -34.79 | I8: =SUMIFS(Data!$I:$I, Data!$F:$F, $B64, Data!$C:$C, ">=" & DATE(2025, MATCH(J$56, {"Jan","Feb","Mar","Apr","May","Jun","Jul","Aug","Sep","Oct","Nov","Dec"}, 0), 1), Data!J:J, "<" & EDATE(DATE(2025, MATCH(J$56, {"Jan","Feb","Mar","Apr","May","Jun","Jul","Aug","Sep","Oct","Nov","Dec"}, 0), 1), 1)) -> 0 | J8: =SUMIFS(Data!$I:$I, Data!$F:$F, $B64, Data!$C:$C, ">=" & DATE(2025, MATCH(K$56, {"Jan","Feb","Mar","Apr","May","Jun","Jul","Aug","Sep","Oct","Nov","Dec"}, 0), 1), Data!K:K, "<" & EDATE(DATE(2025, MATCH(K$56, {"Jan","Feb","Mar","Apr","May","Jun","Jul","Aug","Sep","Oct","Nov","Dec"}, 0), 1), 1)) -> -28.79 | K8: =SUMIFS(Data!$I:$I, Data!$F:$F, $B64, Data!$C:$C, ">=" & DATE(2025, MATCH(L$56, {"Jan","Feb","Mar","Apr","May","Jun","Jul","Aug","Sep","Oct","Nov","Dec"}, 0), 1), Data!L:L, "<" & EDATE(DATE(2025, MATCH(L$56, {"Jan","Feb","Mar","Apr","May","Jun","Jul","Aug","Sep","Oct","Nov","Dec"}, 0), 1), 1)) -> 0 | L8: =SUMIFS(Data!$I:$I, Data!$F:$F, $B64, Data!$C:$C, ">=" & DATE(2025, MATCH(M$56, {"Jan","Feb","Mar","Apr","May","Jun","Jul","Aug","Sep","Oct","Nov","Dec"}, 0), 1), Data!M:M, "<" & EDATE(DATE(2025, MATCH(M$56, {"Jan","Feb","Mar","Apr","May","Jun","Jul","Aug","Sep","Oct","Nov","Dec"}, 0), 1), 1)) -> 0 | M8: =SUMIFS(Data!$I:$I, Data!$F:$F, $B64, Data!$C:$C, ">=" & DATE(2025, MATCH(N$56, {"Jan","Feb","Mar","Apr","May","Jun","Jul","Aug","Sep","Oct","Nov","Dec"}, 0), 1), Data!N:N, "<" & EDATE(DATE(2025, MATCH(N$56, {"Jan","Feb","Mar","Apr","May","Jun","Jul","Aug","Sep","Oct","Nov","Dec"}, 0), 1), 1)) -> 0
A9: Compras | B9: =SUMIFS(Data!I:I, Data!F:F, $B65, Data!C:C, ">=" & DATE(2025, MATCH(C$56, {"Jan","Feb","Mar","Apr","May","Jun","Jul","Aug","Sep","Oct","Nov","Dec"}, 0), 1), Data!C:C, "<" & EDATE(DATE(2025, MATCH(C$56, {"Jan","Feb","Mar","Apr","May","Jun","Jul","Aug","Sep","Oct","Nov","Dec"}, 0), 1), 1)) -> -252.33 | C9: =SUMIFS(Data!$I:$I, Data!$F:$F, $B65, Data!$C:$C, ">=" & DATE(2025, MATCH(D$56, {"Jan","Feb","Mar","Apr","May","Jun","Jul","Aug","Sep","Oct","Nov","Dec"}, 0), 1), Data!D:D, "<" & EDATE(DATE(2025, MATCH(D$56, {"Jan","Feb","Mar","Apr","May","Jun","Jul","Aug","Sep","Oct","Nov","Dec"}, 0), 1), 1)) -> -1231.36 | D9: =SUMIFS(Data!$I:$I, Data!$F:$F, $B65, Data!$C:$C, ">=" & DATE(2025, MATCH(E$56, {"Jan","Feb","Mar","Apr","May","Jun","Jul","Aug","Sep","Oct","Nov","Dec"}, 0), 1), Data!E:E, "<" & EDATE(DATE(2025, MATCH(E$56, {"Jan","Feb","Mar","Apr","May","Jun","Jul","Aug","Sep","Oct","Nov","Dec"}, 0), 1), 1)) -> -1092.27 | E9: =SUMIFS(Data!$I:$I, Data!$F:$F, $B65, Data!$C:$C, ">=" & DATE(2025, MATCH(F$56, {"Jan","Feb","Mar","Apr","May","Jun","Jul","Aug","Sep","Oct","Nov","Dec"}, 0), 1), Data!F:F, "<" & EDATE(DATE(2025, MATCH(F$56, {"Jan","Feb","Mar","Apr","May","Jun","Jul","Aug","Sep","Oct","Nov","Dec"}, 0), 1), 1)) -> 0 | F9: =SUMIFS(Data!$I:$I, Data!$F:$F, $B65, Data!$C:$C, ">=" & DATE(2025, MATCH(G$56, {"Jan","Feb","Mar","Apr","May","Jun","Jul","Aug","Sep","Oct","Nov","Dec"}, 0), 1), Data!G:G, "<" & EDATE(DATE(2025, MATCH(G$56, {"Jan","Feb","Mar","Apr","May","Jun","Jul","Aug","Sep","Oct","Nov","Dec"}, 0), 1), 1)) -> 0 | G9: =SUMIFS(Data!$I:$I, Data!$F:$F, $B65, Data!$C:$C, ">=" & DATE(2025, MATCH(H$56, {"Jan","Feb","Mar","Apr","May","Jun","Jul","Aug","Sep","Oct","Nov","Dec"}, 0), 1), Data!H:H, "<" & EDATE(DATE(2025, MATCH(H$56, {"Jan","Feb","Mar","Apr","May","Jun","Jul","Aug","Sep","Oct","Nov","Dec"}, 0), 1), 1)) -> 0 | H9: =SUMIFS(Data!$I:$I, Data!$F:$F, $B65, Data!$C:$C, ">=" & DATE(2025, MATCH(I$56, {"Jan","Feb","Mar","Apr","May","Jun","Jul","Aug","Sep","Oct","Nov","Dec"}, 0), 1), Data!I:I, "<" & EDATE(DATE(2025, MATCH(I$56, {"Jan","Feb","Mar","Apr","May","Jun","Jul","Aug","Sep","Oct","Nov","Dec"}, 0), 1), 1)) -> -5736.73 | I9: =SUMIFS(Data!$I:$I, Data!$F:$F, $B65, Data!$C:$C, ">=" & DATE(2025, MATCH(J$56, {"Jan","Feb","Mar","Apr","May","Jun","Jul","Aug","Sep","Oct","Nov","Dec"}, 0), 1), Data!J:J, "<" & EDATE(DATE(2025, MATCH(J$56, {"Jan","Feb","Mar","Apr","May","Jun","Jul","Aug","Sep","Oct","Nov","Dec"}, 0), 1), 1)) -> 0 | J9: =SUMIFS(Data!$I:$I, Data!$F:$F, $B65, Data!$C:$C, ">=" & DATE(2025, MATCH(K$56, {"Jan","Feb","Mar","Apr","May","Jun","Jul","Aug","Sep","Oct","Nov","Dec"}, 0), 1), Data!K:K, "<" & EDATE(DATE(2025, MATCH(K$56, {"Jan","Feb","Mar","Apr","May","Jun","Jul","Aug","Sep","Oct","Nov","Dec"}, 0), 1), 1)) -> -5358.32 | K9: =SUMIFS(Data!$I:$I, Data!$F:$F, $B65, Data!$C:$C, ">=" & DATE(2025, MATCH(L$56, {"Jan","Feb","Mar","Apr","May","Jun","Jul","Aug","Sep","Oct","Nov","Dec"}, 0), 1), Data!L:L, "<" & EDATE(DATE(2025, MATCH(L$56, {"Jan","Feb","Mar","Apr","May","Jun","Jul","Aug","Sep","Oct","Nov","Dec"}, 0), 1), 1)) -> 0 | L9: =SUMIFS(Data!$I:$I, Data!$F:$F, $B65, Data!$C:$C, ">=" & DATE(2025, MATCH(M$56, {"Jan","Feb","Mar","Apr","May","Jun","Jul","Aug","Sep","Oct","Nov","Dec"}, 0), 1), Data!M:M, "<" & EDATE(DATE(2025, MATCH(M$56, {"Jan","Feb","Mar","Apr","May","Jun","Jul","Aug","Sep","Oct","Nov","Dec"}, 0), 1), 1)) -> 0 | M9: =SUMIFS(Data!$I:$I, Data!$F:$F, $B65, Data!$C:$C, ">=" & DATE(2025, MATCH(N$56, {"Jan","Feb","Mar","Apr","May","Jun","Jul","Aug","Sep","Oct","Nov","Dec"}, 0), 1), Data!N:N, "<" & EDATE(DATE(2025, MATCH(N$56, {"Jan","Feb","Mar","Apr","May","Jun","Jul","Aug","Sep","Oct","Nov","Dec"}, 0), 1), 1)) -> 0
A10: Deporte | B10: =SUMIFS(Data!I:I, Data!F:F, $B66, Data!C:C, ">=" & DATE(2025, MATCH(C$56, {"Jan","Feb","Mar","Apr","May","Jun","Jul","Aug","Sep","Oct","Nov","Dec"}, 0), 1), Data!C:C, "<" & EDATE(DATE(2025, MATCH(C$56, {"Jan","Feb","Mar","Apr","May","Jun","Jul","Aug","Sep","Oct","Nov","Dec"}, 0), 1), 1)) -> 0 | C10: =SUMIFS(Data!$I:$I, Data!$F:$F, $B66, Data!$C:$C, ">=" & DATE(2025, MATCH(D$56, {"Jan","Feb","Mar","Apr","May","Jun","Jul","Aug","Sep","Oct","Nov","Dec"}, 0), 1), Data!D:D, "<" & EDATE(DATE(2025, MATCH(D$56, {"Jan","Feb","Mar","Apr","May","Jun","Jul","Aug","Sep","Oct","Nov","Dec"}, 0), 1), 1)) -> 0 | D10: =SUMIFS(Data!$I:$I, Data!$F:$F, $B66, Data!$C:$C, ">=" & DATE(2025, MATCH(E$56, {"Jan","Feb","Mar","Apr","May","Jun","Jul","Aug","Sep","Oct","Nov","Dec"}, 0), 1), Data!E:E, "<" & EDATE(DATE(2025, MATCH(E$56, {"Jan","Feb","Mar","Apr","May","Jun","Jul","Aug","Sep","Oct","Nov","Dec"}, 0), 1), 1)) -> 0 | E10: =SUMIFS(Data!$I:$I, Data!$F:$F, $B66, Data!$C:$C, ">=" & DATE(2025, MATCH(F$56, {"Jan","Feb","Mar","Apr","May","Jun","Jul","Aug","Sep","Oct","Nov","Dec"}, 0), 1), Data!F:F, "<" & EDATE(DATE(2025, MATCH(F$56, {"Jan","Feb","Mar","Apr","May","Jun","Jul","Aug","Sep","Oct","Nov","Dec"}, 0), 1), 1)) -> 0 | F10: =SUMIFS(Data!$I:$I, Data!$F:$F, $B66, Data!$C:$C, ">=" & DATE(2025, MATCH(G$56, {"Jan","Feb","Mar","Apr","May","Jun","Jul","Aug","Sep","Oct","Nov","Dec"}, 0), 1), Data!G:G, "<" & EDATE(DATE(2025, MATCH(G$56, {"Jan","Feb","Mar","Apr","May","Jun","Jul","Aug","Sep","Oct","Nov","Dec"}, 0), 1), 1)) -> 0 | G10: =SUMIFS(Data!$I:$I, Data!$F:$F, $B66, Data!$C:$C, ">=" & DATE(2025, MATCH(H$56, {"Jan","Feb","Mar","Apr","May","Jun","Jul","Aug","Sep","Oct","Nov","Dec"}, 0), 1), Data!H:H, "<" & EDATE(DATE(2025, MATCH(H$56, {"Jan","Feb","Mar","Apr","May","Jun","Jul","Aug","Sep","Oct","Nov","Dec"}, 0), 1), 1)) -> 0 | H10: =SUMIFS(Data!$I:$I, Data!$F:$F, $B66, Data!$C:$C, ">=" & DATE(2025, MATCH(I$56, {"Jan","Feb","Mar","Apr","May","Jun","Jul","Aug","Sep","Oct","Nov","Dec"}, 0), 1), Data!I:I, "<" & EDATE(DATE(2025, MATCH(I$56, {"Jan","Feb","Mar","Apr","May","Jun","Jul","Aug","Sep","Oct","Nov","Dec"}, 0), 1), 1)) -> -42.86 | I10: =SUMIFS(Data!$I:$I, Data!$F:$F, $B66, Data!$C:$C, ">=" & DATE(2025, MATCH(J$56, {"Jan","Feb","Mar","Apr","May","Jun","Jul","Aug","Sep","Oct","Nov","Dec"}, 0), 1), Data!J:J, "<" & EDATE(DATE(2025, MATCH(J$56, {"Jan","Feb","Mar","Apr","May","Jun","Jul","Aug","Sep","Oct","Nov","Dec"}, 0), 1), 1)) -> 0 | J10: =SUMIFS(Data!$I:$I, Data!$F:$F, $B66, Data!$C:$C, ">=" & DATE(2025, MATCH(K$56, {"Jan","Feb","Mar","Apr","May","Jun","Jul","Aug","Sep","Oct","Nov","Dec"}, 0), 1), Data!K:K, "<" & EDATE(DATE(2025, MATCH(K$56, {"Jan","Feb","Mar","Apr","May","Jun","Jul","Aug","Sep","Oct","Nov","Dec"}, 0), 1), 1)) -> -42.86 | K10: =SUMIFS(Data!$I:$I, Data!$F:$F, $B66, Data!$C:$C, ">=" & DATE(2025, MATCH(L$56, {"Jan","Feb","Mar","Apr","May","Jun","Jul","Aug","Sep","Oct","Nov","Dec"}, 0), 1), Data!L:L, "<" & EDATE(DATE(2025, MATCH(L$56, {"Jan","Feb","Mar","Apr","May","Jun","Jul","Aug","Sep","Oct","Nov","Dec"}, 0), 1), 1)) -> 0 | L10: =SUMIFS(Data!$I:$I, Data!$F:$F, $B66, Data!$C:$C, ">=" & DATE(2025, MATCH(M$56, {"Jan","Feb","Mar","Apr","May","Jun","Jul","Aug","Sep","Oct","Nov","Dec"}, 0), 1), Data!M:M, "<" & EDATE(DATE(2025, MATCH(M$56, {"Jan","Feb","Mar","Apr","May","Jun","Jul","Aug","Sep","Oct","Nov","Dec"}, 0), 1), 1)) -> 0 | M10: =SUMIFS(Data!$I:$I, Data!$F:$F, $B66, Data!$C:$C, ">=" & DATE(2025, MATCH(N$56, {"Jan","Feb","Mar","Apr","May","Jun","Jul","Aug","Sep","Oct","Nov","Dec"}, 0), 1), Data!N:N, "<" & EDATE(DATE(2025, MATCH(N$56, {"Jan","Feb","Mar","Apr","May","Jun","Jul","Aug","Sep","Oct","Nov","Dec"}, 0), 1), 1)) -> 0
A11: Deudas | B11: =SUMIFS(Data!I:I, Data!F:F, $B67, Data!C:C, ">=" & DATE(2025, MATCH(C$56, {"Jan","Feb","Mar","Apr","May","Jun","Jul","Aug","Sep","Oct","Nov","Dec"}, 0), 1), Data!C:C, "<" & EDATE(DATE(2025, MATCH(C$56, {"Jan","Feb","Mar","Apr","May","Jun","Jul","Aug","Sep","Oct","Nov","Dec"}, 0), 1), 1)) -> -68.32 | C11: =SUMIFS(Data!$I:$I, Data!$F:$F, $B67, Data!$C:$C, ">=" & DATE(2025, MATCH(D$56, {"Jan","Feb","Mar","Apr","May","Jun","Jul","Aug","Sep","Oct","Nov","Dec"}, 0), 1), Data!D:D, "<" & EDATE(DATE(2025, MATCH(D$56, {"Jan","Feb","Mar","Apr","May","Jun","Jul","Aug","Sep","Oct","Nov","Dec"}, 0), 1), 1)) -> -136.64 | D11: =SUMIFS(Data!$I:$I, Data!$F:$F, $B67, Data!$C:$C, ">=" & DATE(2025, MATCH(E$56, {"Jan","Feb","Mar","Apr","May","Jun","Jul","Aug","Sep","Oct","Nov","Dec"}, 0), 1), Data!E:E, "<" & EDATE(DATE(2025, MATCH(E$56, {"Jan","Feb","Mar","Apr","May","Jun","Jul","Aug","Sep","Oct","Nov","Dec"}, 0), 1), 1)) -> 0 | E11: =SUMIFS(Data!$I:$I, Data!$F:$F, $B67, Data!$C:$C, ">=" & DATE(2025, MATCH(F$56, {"Jan","Feb","Mar","Apr","May","Jun","Jul","Aug","Sep","Oct","Nov","Dec"}, 0), 1), Data!F:F, "<" & EDATE(DATE(2025, MATCH(F$56, {"Jan","Feb","Mar","Apr","May","Jun","Jul","Aug","Sep","Oct","Nov","Dec"}, 0), 1), 1)) -> 0 | F11: =SUMIFS(Data!$I:$I, Data!$F:$F, $B67, Data!$C:$C, ">=" & DATE(2025, MATCH(G$56, {"Jan","Feb","Mar","Apr","May","Jun","Jul","Aug","Sep","Oct","Nov","Dec"}, 0), 1), Data!G:G, "<" & EDATE(DATE(2025, MATCH(G$56, {"Jan","Feb","Mar","Apr","May","Jun","Jul","Aug","Sep","Oct","Nov","Dec"}, 0), 1), 1)) -> 0 | G11: =SUMIFS(Data!$I:$I, Data!$F:$F, $B67, Data!$C:$C, ">=" & DATE(2025, MATCH(H$56, {"Jan","Feb","Mar","Apr","May","Jun","Jul","Aug","Sep","Oct","Nov","Dec"}, 0), 1), Data!H:H, "<" & EDATE(DATE(2025, MATCH(H$56, {"Jan","Feb","Mar","Apr","May","Jun","Jul","Aug","Sep","Oct","Nov","Dec"}, 0), 1), 1)) -> 0 | H11: =SUMIFS(Data!$I:$I, Data!$F:$F, $B67, Data!$C:$C, ">=" & DATE(2025, MATCH(I$56, {"Jan","Feb","Mar","Apr","May","Jun","Jul","Aug","Sep","Oct","Nov","Dec"}, 0), 1), Data!I:I, "<" & EDATE(DATE(2025, MATCH(I$56, {"Jan","Feb","Mar","Apr","May","Jun","Jul","Aug","Sep","Oct","Nov","Dec"}, 0), 1), 1)) -> -36 | I11: =SUMIFS(Data!$I:$I, Data!$F:$F, $B67, Data!$C:$C, ">=" & DATE(2025, MATCH(J$56, {"Jan","Feb","Mar","Apr","May","Jun","Jul","Aug","Sep","Oct","Nov","Dec"}, 0), 1), Data!J:J, "<" & EDATE(DATE(2025, MATCH(J$56, {"Jan","Feb","Mar","Apr","May","Jun","Jul","Aug","Sep","Oct","Nov","Dec"}, 0), 1), 1)) -> 0 | J11: =SUMIFS(Data!$I:$I, Data!$F:$F, $B67, Data!$C:$C, ">=" & DATE(2025, MATCH(K$56, {"Jan","Feb","Mar","Apr","May","Jun","Jul","Aug","Sep","Oct","Nov","Dec"}, 0), 1), Data!K:K, "<" & EDATE(DATE(2025, MATCH(K$56, {"Jan","Feb","Mar","Apr","May","Jun","Jul","Aug","Sep","Oct","Nov","Dec"}, 0), 1), 1)) -> -36 | K11: =SUMIFS(Data!$I:$I, Data!$F:$F, $B67, Data!$C:$C, ">=" & DATE(2025, MATCH(L$56, {"Jan","Feb","Mar","Apr","May","Jun","Jul","Aug","Sep","Oct","Nov","Dec"}, 0), 1), Data!L:L, "<" & EDATE(DATE(2025, MATCH(L$56, {"Jan","Feb","Mar","Apr","May","Jun","Jul","Aug","Sep","Oct","Nov","Dec"}, 0), 1), 1)) -> 0 | L11: =SUMIFS(Data!$I:$I, Data!$F:$F, $B67, Data!$C:$C, ">=" & DATE(2025, MATCH(M$56, {"Jan","Feb","Mar","Apr","May","Jun","Jul","Aug","Sep","Oct","Nov","Dec"}, 0), 1), Data!M:M, "<" & EDATE(DATE(2025, MATCH(M$56, {"Jan","Feb","Mar","Apr","May","Jun","Jul","Aug","Sep","Oct","Nov","Dec"}, 0), 1), 1)) -> 0 | M11: =SUMIFS(Data!$I:$I, Data!$F:$F, $B67, Data!$C:$C, ">=" & DATE(2025, MATCH(N$56, {"Jan","Feb","Mar","Apr","May","Jun","Jul","Aug","Sep","Oct","Nov","Dec"}, 0), 1), Data!N:N, "<" & EDATE(DATE(2025, MATCH(N$56, {"Jan","Feb","Mar","Apr","May","Jun","Jul","Aug","Sep","Oct","Nov","Dec"}, 0), 1), 1)) -> 0
A12: Donación | B12: =SUMIFS(Data!I:I, Data!F:F, $B68, Data!C:C, ">=" & DATE(2025, MATCH(C$56, {"Jan","Feb","Mar","Apr","May","Jun","Jul","Aug","Sep","Oct","Nov","Dec"}, 0), 1), Data!C:C, "<" & EDATE(DATE(2025, MATCH(C$56, {"Jan","Feb","Mar","Apr","May","Jun","Jul","Aug","Sep","Oct","Nov","Dec"}, 0), 1), 1)) -> 0 | C12: =SUMIFS(Data!$I:$I, Data!$F:$F, $B68, Data!$C:$C, ">=" & DATE(2025, MATCH(D$56, {"Jan","Feb","Mar","Apr","May","Jun","Jul","Aug","Sep","Oct","Nov","Dec"}, 0), 1), Data!D:D, "<" & EDATE(DATE(2025, MATCH(D$56, {"Jan","Feb","Mar","Apr","May","Jun","Jul","Aug","Sep","Oct","Nov","Dec"}, 0), 1), 1)) -> 0 | D12: =SUMIFS(Data!$I:$I, Data!$F:$F, $B68, Data!$C:$C, ">=" & DATE(2025, MATCH(E$56, {"Jan","Feb","Mar","Apr","May","Jun","Jul","Aug","Sep","Oct","Nov","Dec"}, 0), 1), Data!E:E, "<" & EDATE(DATE(2025, MATCH(E$56, {"Jan","Feb","Mar","Apr","May","Jun","Jul","Aug","Sep","Oct","Nov","Dec"}, 0), 1), 1)) -> 0 | E12: =SUMIFS(Data!$I:$I, Data!$F:$F, $B68, Data!$C:$C, ">=" & DATE(2025, MATCH(F$56, {"Jan","Feb","Mar","Apr","May","Jun","Jul","Aug","Sep","Oct","Nov","Dec"}, 0), 1), Data!F:F, "<" & EDATE(DATE(2025, MATCH(F$56, {"Jan","Feb","Mar","Apr","May","Jun","Jul","Aug","Sep","Oct","Nov","Dec"}, 0), 1), 1)) -> 0 | F12: =SUMIFS(Data!$I:$I, Data!$F:$F, $B68, Data!$C:$C, ">=" & DATE(2025, MATCH(G$56, {"Jan","Feb","Mar","Apr","May","Jun","Jul","Aug","Sep","Oct","Nov","Dec"}, 0), 1), Data!G:G, "<" & EDATE(DATE(2025, MATCH(G$56, {"Jan","Feb","Mar","Apr","May","Jun","Jul","Aug","Sep","Oct","Nov","Dec"}, 0), 1), 1)) -> 0 | G12: =SUMIFS(Data!$I:$I, Data!$F:$F, $B68, Data!$C:$C, ">=" & DATE(2025, MATCH(H$56, {"Jan","Feb","Mar","Apr","May","Jun","Jul","Aug","Sep","Oct","Nov","Dec"}, 0), 1), Data!H:H, "<" & EDATE(DATE(2025, MATCH(H$56, {"Jan","Feb","Mar","Apr","May","Jun","Jul","Aug","Sep","Oct","Nov","Dec"}, 0), 1), 1)) -> 0 | H12: =SUMIFS(Data!$I:$I, Data!$F:$F, $B68, Data!$C:$C, ">=" & DATE(2025, MATCH(I$56, {"Jan","Feb","Mar","Apr","May","Jun","Jul","Aug","Sep","Oct","Nov","Dec"}, 0), 1), Data!I:I, "<" & EDATE(DATE(2025, MATCH(I$56, {"Jan","Feb","Mar","Apr","May","Jun","Jul","Aug","Sep","Oct","Nov","Dec"}, 0), 1), 1)) -> 0 | I12: =SUMIFS(Data!$I:$I, Data!$F:$F, $B68, Data!$C:$C, ">=" & DATE(2025, MATCH(J$56, {"Jan","Feb","Mar","Apr","May","Jun","Jul","Aug","Sep","Oct","Nov","Dec"}, 0), 1), Data!J:J, "<" & EDATE(DATE(2025, MATCH(J$56, {"Jan","Feb","Mar","Apr","May","Jun","Jul","Aug","Sep","Oct","Nov","Dec"}, 0), 1), 1)) -> 0 | J12: =SUMIFS(Data!$I:$I, Data!$F:$F, $B68, Data!$C:$C, ">=" & DATE(2025, MATCH(K$56, {"Jan","Feb","Mar","Apr","May","Jun","Jul","Aug","Sep","Oct","Nov","Dec"}, 0), 1), Data!K:K, "<" & EDATE(DATE(2025, MATCH(K$56, {"Jan","Feb","Mar","Apr","May","Jun","Jul","Aug","Sep","Oct","Nov","Dec"}, 0), 1), 1)) -> 0 | K12: =SUMIFS(Data!$I:$I, Data!$F:$F, $B68, Data!$C:$C, ">=" & DATE(2025, MATCH(L$56, {"Jan","Feb","Mar","Apr","May","Jun","Jul","Aug","Sep","Oct","Nov","Dec"}, 0), 1), Data!L:L, "<" & EDATE(DATE(2025, MATCH(L$56, {"Jan","Feb","Mar","Apr","May","Jun","Jul","Aug","Sep","Oct","Nov","Dec"}, 0), 1), 1)) -> 0 | L12: =SUMIFS(Data!$I:$I, Data!$F:$F, $B68, Data!$C:$C, ">=" & DATE(2025, MATCH(M$56, {"Jan","Feb","Mar","Apr","May","Jun","Jul","Aug","Sep","Oct","Nov","Dec"}, 0), 1), Data!M:M, "<" & EDATE(DATE(2025, MATCH(M$56, {"Jan","Feb","Mar","Apr","May","Jun","Jul","Aug","Sep","Oct","Nov","Dec"}, 0), 1), 1)) -> 0 | M12: =SUMIFS(Data!$I:$I, Data!$F:$F, $B68, Data!$C:$C, ">=" & DATE(2025, MATCH(N$56, {"Jan","Feb","Mar","Apr","May","Jun","Jul","Aug","Sep","Oct","Nov","Dec"}, 0), 1), Data!N:N, "<" & EDATE(DATE(2025, MATCH(N$56, {"Jan","Feb","Mar","Apr","May","Jun","Jul","Aug","Sep","Oct","Nov","Dec"}, 0), 1), 1)) -> 0
A13: E'Kabel | B13: =SUMIFS(Data!I:I, Data!F:F, $B69, Data!C:C, ">=" & DATE(2025, MATCH(C$56, {"Jan","Feb","Mar","Apr","May","Jun","Jul","Aug","Sep","Oct","Nov","Dec"}, 0), 1), Data!C:C, "<" & EDATE(DATE(2025, MATCH(C$56, {"Jan","Feb","Mar","Apr","May","Jun","Jul","Aug","Sep","Oct","Nov","Dec"}, 0), 1), 1)) -> 0 | C13: =SUMIFS(Data!$I:$I, Data!$F:$F, $B69, Data!$C:$C, ">=" & DATE(2025, MATCH(D$56, {"Jan","Feb","Mar","Apr","May","Jun","Jul","Aug","Sep","Oct","Nov","Dec"}, 0), 1), Data!D:D, "<" & EDATE(DATE(2025, MATCH(D$56, {"Jan","Feb","Mar","Apr","May","Jun","Jul","Aug","Sep","Oct","Nov","Dec"}, 0), 1), 1)) -> 0 | D13: =SUMIFS(Data!$I:$I, Data!$F:$F, $B69, Data!$C:$C, ">=" & DATE(2025, MATCH(E$56, {"Jan","Feb","Mar","Apr","May","Jun","Jul","Aug","Sep","Oct","Nov","Dec"}, 0), 1), Data!E:E, "<" & EDATE(DATE(2025, MATCH(E$56, {"Jan","Feb","Mar","Apr","May","Jun","Jul","Aug","Sep","Oct","Nov","Dec"}, 0), 1), 1)) -> 0 | E13: =SUMIFS(Data!$I:$I, Data!$F:$F, $B69, Data!$C:$C, ">=" & DATE(2025, MATCH(F$56, {"Jan","Feb","Mar","Apr","May","Jun","Jul","Aug","Sep","Oct","Nov","Dec"}, 0), 1), Data!F:F, "<" & EDATE(DATE(2025, MATCH(F$56, {"Jan","Feb","Mar","Apr","May","Jun","Jul","Aug","Sep","Oct","Nov","Dec"}, 0), 1), 1)) -> 0 | F13: =SUMIFS(Data!$I:$I, Data!$F:$F, $B69, Data!$C:$C, ">=" & DATE(2025, MATCH(G$56, {"Jan","Feb","Mar","Apr","May","Jun","Jul","Aug","Sep","Oct","Nov","Dec"}, 0), 1), Data!G:G, "<" & EDATE(DATE(2025, MATCH(G$56, {"Jan","Feb","Mar","Apr","May","Jun","Jul","Aug","Sep","Oct","Nov","Dec"}, 0), 1), 1)) -> 0 | G13: =SUMIFS(Data!$I:$I, Data!$F:$F, $B69, Data!$C:$C, ">=" & DATE(2025, MATCH(H$56, {"Jan","Feb","Mar","Apr","May","Jun","Jul","Aug","Sep","Oct","Nov","Dec"}, 0), 1), Data!H:H, "<" & EDATE(DATE(2025, MATCH(H$56, {"Jan","Feb","Mar","Apr","May","Jun","Jul","Aug","Sep","Oct","Nov","Dec"}, 0), 1), 1)) -> 0 | H13: =SUMIFS(Data!$I:$I, Data!$F:$F, $B69, Data!$C:$C, ">=" & DATE(2025, MATCH(I$56, {"Jan","Feb","Mar","Apr","May","Jun","Jul","Aug","Sep","Oct","Nov","Dec"}, 0), 1), Data!I:I, "<" & EDATE(DATE(2025, MATCH(I$56, {"Jan","Feb","Mar","Apr","May","Jun","Jul","Aug","Sep","Oct","Nov","Dec"}, 0), 1), 1)) -> 0 | I13: =SUMIFS(Data!$I:$I, Data!$F:$F, $B69, Data!$C:$C, ">=" & DATE(2025, MATCH(J$56, {"Jan","Feb","Mar","Apr","May","Jun","Jul","Aug","Sep","Oct","Nov","Dec"}, 0), 1), Data!J:J, "<" & EDATE(DATE(2025, MATCH(J$56, {"Jan","Feb","Mar","Apr","May","Jun","Jul","Aug","Sep","Oct","Nov","Dec"}, 0), 1), 1)) -> 0 | J13: =SUMIFS(Data!$I:$I, Data!$F:$F, $B69, Data!$C:$C, ">=" & DATE(2025, MATCH(K$56, {"Jan","Feb","Mar","Apr","May","Jun","Jul","Aug","Sep","Oct","Nov","Dec"}, 0), 1), Data!K:K, "<" & EDATE(DATE(2025, MATCH(K$56, {"Jan","Feb","Mar","Apr","May","Jun","Jul","Aug","Sep","Oct","Nov","Dec"}, 0), 1), 1)) -> 0 | K13: =SUMIFS(Data!$I:$I, Data!$F:$F, $B69, Data!$C:$C, ">=" & DATE(2025, MATCH(L$56, {"Jan","Feb","Mar","Apr","May","Jun","Jul","Aug","Sep","Oct","Nov","Dec"}, 0), 1), Data!L:L, "<" & EDATE(DATE(2025, MATCH(L$56, {"Jan","Feb","Mar","Apr","May","Jun","Jul","Aug","Sep","Oct","Nov","Dec"}, 0), 1), 1)) -> 0 | L13: =SUMIFS(Data!$I:$I, Data!$F:$F, $B69, Data!$C:$C, ">=" & DATE(2025, MATCH(M$56, {"Jan","Feb","Mar","Apr","May","Jun","Jul","Aug","Sep","Oct","Nov","Dec"}, 0), 1), Data!M:M, "<" & EDATE(DATE(2025, MATCH(M$56, {"Jan","Feb","Mar","Apr","May","Jun","Jul","Aug","Sep","Oct","Nov","Dec"}, 0), 1), 1)) -> 0 | M13: =SUMIFS(Data!$I:$I, Data!$F:$F, $B69, Data!$C:$C, ">=" & DATE(2025, MATCH(N$56, {"Jan","Feb","Mar","Apr","May","Jun","Jul","Aug","Sep","Oct","Nov","Dec"}, 0), 1), Data!N:N, "<" & EDATE(DATE(2025, MATCH(N$56, {"Jan","Feb","Mar","Apr","May","Jun","Jul","Aug","Sep","Oct","Nov","Dec"}, 0), 1), 1)) -> 0
A14: Entretenimiento | B14: =SUMIFS(Data!I:I, Data!F:F, $B70, Data!C:C, ">=" & DATE(2025, MATCH(C$56, {"Jan","Feb","Mar","Apr","May","Jun","Jul","Aug","Sep","Oct","Nov","Dec"}, 0), 1), Data!C:C, "<" & EDATE(DATE(2025, MATCH(C$56, {"Jan","Feb","Mar","Apr","May","Jun","Jul","Aug","Sep","Oct","Nov","Dec"}, 0), 1), 1)) -> -818.57 | C14: =SUMIFS(Data!$I:$I, Data!$F:$F, $B70, Data!$C:$C, ">=" & DATE(2025, MATCH(D$56, {"Jan","Feb","Mar","Apr","May","Jun","Jul","Aug","Sep","Oct","Nov","Dec"}, 0), 1), Data!D:D, "<" & EDATE(DATE(2025, MATCH(D$56, {"Jan","Feb","Mar","Apr","May","Jun","Jul","Aug","Sep","Oct","Nov","Dec"}, 0), 1), 1)) -> -792.61 | D14: =SUMIFS(Data!$I:$I, Data!$F:$F, $B70, Data!$C:$C, ">=" & DATE(2025, MATCH(E$56, {"Jan","Feb","Mar","Apr","May","Jun","Jul","Aug","Sep","Oct","Nov","Dec"}, 0), 1), Data!E:E, "<" & EDATE(DATE(2025, MATCH(E$56, {"Jan","Feb","Mar","Apr","May","Jun","Jul","Aug","Sep","Oct","Nov","Dec"}, 0), 1), 1)) -> -787.25 | E14: =SUMIFS(Data!$I:$I, Data!$F:$F, $B70, Data!$C:$C, ">=" & DATE(2025, MATCH(F$56, {"Jan","Feb","Mar","Apr","May","Jun","Jul","Aug","Sep","Oct","Nov","Dec"}, 0), 1), Data!F:F, "<" & EDATE(DATE(2025, MATCH(F$56, {"Jan","Feb","Mar","Apr","May","Jun","Jul","Aug","Sep","Oct","Nov","Dec"}, 0), 1), 1)) -> 0 | F14: =SUMIFS(Data!$I:$I, Data!$F:$F, $B70, Data!$C:$C, ">=" & DATE(2025, MATCH(G$56, {"Jan","Feb","Mar","Apr","May","Jun","Jul","Aug","Sep","Oct","Nov","Dec"}, 0), 1), Data!G:G, "<" & EDATE(DATE(2025, MATCH(G$56, {"Jan","Feb","Mar","Apr","May","Jun","Jul","Aug","Sep","Oct","Nov","Dec"}, 0), 1), 1)) -> 0 | G14: =SUMIFS(Data!$I:$I, Data!$F:$F, $B70, Data!$C:$C, ">=" & DATE(2025, MATCH(H$56, {"Jan","Feb","Mar","Apr","May","Jun","Jul","Aug","Sep","Oct","Nov","Dec"}, 0), 1), Data!H:H, "<" & EDATE(DATE(2025, MATCH(H$56, {"Jan","Feb","Mar","Apr","May","Jun","Jul","Aug","Sep","Oct","Nov","Dec"}, 0), 1), 1)) -> 0 | H14: =SUMIFS(Data!$I:$I, Data!$F:$F, $B70, Data!$C:$C, ">=" & DATE(2025, MATCH(I$56, {"Jan","Feb","Mar","Apr","May","Jun","Jul","Aug","Sep","Oct","Nov","Dec"}, 0), 1), Data!I:I, "<" & EDATE(DATE(2025, MATCH(I$56, {"Jan","Feb","Mar","Apr","May","Jun","Jul","Aug","Sep","Oct","Nov","Dec"}, 0), 1), 1)) -> -8052.66 | I14: =SUMIFS(Data!$I:$I, Data!$F:$F, $B70, Data!$C:$C, ">=" & DATE(2025, MATCH(J$56, {"Jan","Feb","Mar","Apr","May","Jun","Jul","Aug","Sep","Oct","Nov","Dec"}, 0), 1), Data!J:J, "<" & EDATE(DATE(2025, MATCH(J$56, {"Jan","Feb","Mar","Apr","May","Jun","Jul","Aug","Sep","Oct","Nov","Dec"}, 0), 1), 1)) -> 0 | J14: =SUMIFS(Data!$I:$I, Data!$F:$F, $B70, Data!$C:$C, ">=" & DATE(2025, MATCH(K$56, {"Jan","Feb","Mar","Apr","May","Jun","Jul","Aug","Sep","Oct","Nov","Dec"}, 0), 1), Data!K:K, "<" & EDATE(DATE(2025, MATCH(K$56, {"Jan","Feb","Mar","Apr","May","Jun","Jul","Aug","Sep","Oct","Nov","Dec"}, 0), 1), 1)) -> -5795.58 | K14: =SUMIFS(Data!$I:$I, Data!$F:$F, $B70, Data!$C:$C, ">=" & DATE(2025, MATCH(L$56, {"Jan","Feb","Mar","Apr","May","Jun","Jul","Aug","Sep","Oct","Nov","Dec"}, 0), 1), Data!L:L, "<" & EDATE(DATE(2025, MATCH(L$56, {"Jan","Feb","Mar","Apr","May","Jun","Jul","Aug","Sep","Oct","Nov","Dec"}, 0), 1), 1)) -> 0 | L14: =SUMIFS(Data!$I:$I, Data!$F:$F, $B70, Data!$C:$C, ">=" & DATE(2025, MATCH(M$56, {"Jan","Feb","Mar","Apr","May","Jun","Jul","Aug","Sep","Oct","Nov","Dec"}, 0), 1), Data!M:M, "<" & EDATE(DATE(2025, MATCH(M$56, {"Jan","Feb","Mar","Apr","May","Jun","Jul","Aug","Sep","Oct","Nov","Dec"}, 0), 1), 1)) -> 0 | M14: =SUMIFS(Data!$I:$I, Data!$F:$F, $B70, Data!$C:$C, ">=" & DATE(2025, MATCH(N$56, {"Jan","Feb","Mar","Apr","May","Jun","Jul","Aug","Sep","Oct","Nov","Dec"}, 0), 1), Data!N:N, "<" & EDATE(DATE(2025, MATCH(N$56, {"Jan","Feb","Mar","Apr","May","Jun","Jul","Aug","Sep","Oct","Nov","Dec"}, 0), 1), 1)) -> 0
A15: Establecernos | B15: =SUMIFS(Data!I:I, Data!F:F, $B71, Data!C:C, ">=" & DATE(2025, MATCH(C$56, {"Jan","Feb","Mar","Apr","May","Jun","Jul","Aug","Sep","Oct","Nov","Dec"}, 0), 1), Data!C:C, "<" & EDATE(DATE(2025, MATCH(C$56, {"Jan","Feb","Mar","Apr","May","Jun","Jul","Aug","Sep","Oct","Nov","Dec"}, 0), 1), 1)) -> 0 | C15: =SUMIFS(Data!$I:$I, Data!$F:$F, $B71, Data!$C:$C, ">=" & DATE(2025, MATCH(D$56, {"Jan","Feb","Mar","Apr","May","Jun","Jul","Aug","Sep","Oct","Nov","Dec"}, 0), 1), Data!D:D, "<" & EDATE(DATE(2025, MATCH(D$56, {"Jan","Feb","Mar","Apr","May","Jun","Jul","Aug","Sep","Oct","Nov","Dec"}, 0), 1), 1)) -> 0 | D15: =SUMIFS(Data!$I:$I, Data!$F:$F, $B71, Data!$C:$C, ">=" & DATE(2025, MATCH(E$56, {"Jan","Feb","Mar","Apr","May","Jun","Jul","Aug","Sep","Oct","Nov","Dec"}, 0), 1), Data!E:E, "<" & EDATE(DATE(2025, MATCH(E$56, {"Jan","Feb","Mar","Apr","May","Jun","Jul","Aug","Sep","Oct","Nov","Dec"}, 0), 1), 1)) -> 0 | E15: =SUMIFS(Data!$I:$I, Data!$F:$F, $B71, Data!$C:$C, ">=" & DATE(2025, MATCH(F$56, {"Jan","Feb","Mar","Apr","May","Jun","Jul","Aug","Sep","Oct","Nov","Dec"}, 0), 1), Data!F:F, "<" & EDATE(DATE(2025, MATCH(F$56, {"Jan","Feb","Mar","Apr","May","Jun","Jul","Aug","Sep","Oct","Nov","Dec"}, 0), 1), 1)) -> 0 | F15: =SUMIFS(Data!$I:$I, Data!$F:$F, $B71, Data!$C:$C, ">=" & DATE(2025, MATCH(G$56, {"Jan","Feb","Mar","Apr","May","Jun","Jul","Aug","Sep","Oct","Nov","Dec"}, 0), 1), Data!G:G, "<" & EDATE(DATE(2025, MATCH(G$56, {"Jan","Feb","Mar","Apr","May","Jun","Jul","Aug","Sep","Oct","Nov","Dec"}, 0), 1), 1)) -> 0 | G15: =SUMIFS(Data!$I:$I, Data!$F:$F, $B71, Data!$C:$C, ">=" & DATE(2025, MATCH(H$56, {"Jan","Feb","Mar","Apr","May","Jun","Jul","Aug","Sep","Oct","Nov","Dec"}, 0), 1), Data!H:H, "<" & EDATE(DATE(2025, MATCH(H$56, {"Jan","Feb","Mar","Apr","May","Jun","Jul","Aug","Sep","Oct","Nov","Dec"}, 0), 1), 1)) -> 0 | H15: =SUMIFS(Data!$I:$I, Data!$F:$F, $B71, Data!$C:$C, ">=" & DATE(2025, MATCH(I$56, {"Jan","Feb","Mar","Apr","May","Jun","Jul","Aug","Sep","Oct","Nov","Dec"}, 0), 1), Data!I:I, "<" & EDATE(DATE(2025, MATCH(I$56, {"Jan","Feb","Mar","Apr","May","Jun","Jul","Aug","Sep","Oct","Nov","Dec"}, 0), 1), 1)) -> 0 | I15: =SUMIFS(Data!$I:$I, Data!$F:$F, $B71, Data!$C:$C, ">=" & DATE(2025, MATCH(J$56, {"Jan","Feb","Mar","Apr","May","Jun","Jul","Aug","Sep","Oct","Nov","Dec"}, 0), 1), Data!J:J, "<" & EDATE(DATE(2025, MATCH(J$56, {"Jan","Feb","Mar","Apr","May","Jun","Jul","Aug","Sep","Oct","Nov","Dec"}, 0), 1), 1)) -> 0 | J15: =SUMIFS(Data!$I:$I, Data!$F:$F, $B71, Data!$C:$C, ">=" & DATE(2025, MATCH(K$56, {"Jan","Feb","Mar","Apr","May","Jun","Jul","Aug","Sep","Oct","Nov","Dec"}, 0), 1), Data!K:K, "<" & EDATE(DATE(2025, MATCH(K$56, {"Jan","Feb","Mar","Apr","May","Jun","Jul","Aug","Sep","Oct","Nov","Dec"}, 0), 1), 1)) -> 0 | K15: =SUMIFS(Data!$I:$I, Data!$F:$F, $B71, Data!$C:$C, ">=" & DATE(2025, MATCH(L$56, {"Jan","Feb","Mar","Apr","May","Jun","Jul","Aug","Sep","Oct","Nov","Dec"}, 0), 1), Data!L:L, "<" & EDATE(DATE(2025, MATCH(L$56, {"Jan","Feb","Mar","Apr","May","Jun","Jul","Aug","Sep","Oct","Nov","Dec"}, 0), 1), 1)) -> 0 | L15: =SUMIFS(Data!$I:$I, Data!$F:$F, $B71, Data!$C:$C, ">=" & DATE(2025, MATCH(M$56, {"Jan","Feb","Mar","Apr","May","Jun","Jul","Aug","Sep","Oct","Nov","Dec"}, 0), 1), Data!M:M, "<" & EDATE(DATE(2025, MATCH(M$56, {"Jan","Feb","Mar","Apr","May","Jun","Jul","Aug","Sep","Oct","Nov","Dec"}, 0), 1), 1)) -> 0 | M15: =SUMIFS(Data!$I:$I, Data!$F:$F, $B71, Data!$C:$C, ">=" & DATE(2025, MATCH(N$56, {"Jan","Feb","Mar","Apr","May","Jun","Jul","Aug","Sep","Oct","Nov","Dec"}, 0), 1), Data!N:N, "<" & EDATE(DATE(2025, MATCH(N$56, {"Jan","Feb","Mar","Apr","May","Jun","Jul","Aug","Sep","Oct","Nov","Dec"}, 0), 1), 1)) -> 0
A16: Financiero | B16: =SUMIFS(Data!I:I, Data!F:F, $B72, Data!C:C, ">=" & DATE(2025, MATCH(C$56, {"Jan","Feb","Mar","Apr","May","Jun","Jul","Aug","Sep","Oct","Nov","Dec"}, 0), 1), Data!C:C, "<" & EDATE(DATE(2025, MATCH(C$56, {"Jan","Feb","Mar","Apr","May","Jun","Jul","Aug","Sep","Oct","Nov","Dec"}, 0), 1), 1)) -> -1.32 | C16: =SUMIFS(Data!$I:$I, Data!$F:$F, $B72, Data!$C:$C, ">=" & DATE(2025, MATCH(D$56, {"Jan","Feb","Mar","Apr","May","Jun","Jul","Aug","Sep","Oct","Nov","Dec"}, 0), 1), Data!D:D, "<" & EDATE(DATE(2025, MATCH(D$56, {"Jan","Feb","Mar","Apr","May","Jun","Jul","Aug","Sep","Oct","Nov","Dec"}, 0), 1), 1)) -> -231.07 | D16: =SUMIFS(Data!$I:$I, Data!$F:$F, $B72, Data!$C:$C, ">=" & DATE(2025, MATCH(E$56, {"Jan","Feb","Mar","Apr","May","Jun","Jul","Aug","Sep","Oct","Nov","Dec"}, 0), 1), Data!E:E, "<" & EDATE(DATE(2025, MATCH(E$56, {"Jan","Feb","Mar","Apr","May","Jun","Jul","Aug","Sep","Oct","Nov","Dec"}, 0), 1), 1)) -> -0.58 | E16: =SUMIFS(Data!$I:$I, Data!$F:$F, $B72, Data!$C:$C, ">=" & DATE(2025, MATCH(F$56, {"Jan","Feb","Mar","Apr","May","Jun","Jul","Aug","Sep","Oct","Nov","Dec"}, 0), 1), Data!F:F, "<" & EDATE(DATE(2025, MATCH(F$56, {"Jan","Feb","Mar","Apr","May","Jun","Jul","Aug","Sep","Oct","Nov","Dec"}, 0), 1), 1)) -> 0 | F16: =SUMIFS(Data!$I:$I, Data!$F:$F, $B72, Data!$C:$C, ">=" & DATE(2025, MATCH(G$56, {"Jan","Feb","Mar","Apr","May","Jun","Jul","Aug","Sep","Oct","Nov","Dec"}, 0), 1), Data!G:G, "<" & EDATE(DATE(2025, MATCH(G$56, {"Jan","Feb","Mar","Apr","May","Jun","Jul","Aug","Sep","Oct","Nov","Dec"}, 0), 1), 1)) -> 0 | G16: =SUMIFS(Data!$I:$I, Data!$F:$F, $B72, Data!$C:$C, ">=" & DATE(2025, MATCH(H$56, {"Jan","Feb","Mar","Apr","May","Jun","Jul","Aug","Sep","Oct","Nov","Dec"}, 0), 1), Data!H:H, "<" & EDATE(DATE(2025, MATCH(H$56, {"Jan","Feb","Mar","Apr","May","Jun","Jul","Aug","Sep","Oct","Nov","Dec"}, 0), 1), 1)) -> 0 | H16: =SUMIFS(Data!$I:$I, Data!$F:$F, $B72, Data!$C:$C, ">=" & DATE(2025, MATCH(I$56, {"Jan","Feb","Mar","Apr","May","Jun","Jul","Aug","Sep","Oct","Nov","Dec"}, 0), 1), Data!I:I, "<" & EDATE(DATE(2025, MATCH(I$56, {"Jan","Feb","Mar","Apr","May","Jun","Jul","Aug","Sep","Oct","Nov","Dec"}, 0), 1), 1)) -> -467.27 | I16: =SUMIFS(Data!$I:$I, Data!$F:$F, $B72, Data!$C:$C, ">=" & DATE(2025, MATCH(J$56, {"Jan","Feb","Mar","Apr","May","Jun","Jul","Aug","Sep","Oct","Nov","Dec"}, 0), 1), Data!J:J, "<" & EDATE(DATE(2025, MATCH(J$56, {"Jan","Feb","Mar","Apr","May","Jun","Jul","Aug","Sep","Oct","Nov","Dec"}, 0), 1), 1)) -> 0 | J16: =SUMIFS(Data!$I:$I, Data!$F:$F, $B72, Data!$C:$C, ">=" & DATE(2025, MATCH(K$56, {"Jan","Feb","Mar","Apr","May","Jun","Jul","Aug","Sep","Oct","Nov","Dec"}, 0), 1), Data!K:K, "<" & EDATE(DATE(2025, MATCH(K$56, {"Jan","Feb","Mar","Apr","May","Jun","Jul","Aug","Sep","Oct","Nov","Dec"}, 0), 1), 1)) -> -464.22 | K16: =SUMIFS(Data!$I:$I, Data!$F:$F, $B72, Data!$C:$C, ">=" & DATE(2025, MATCH(L$56, {"Jan","Feb","Mar","Apr","May","Jun","Jul","Aug","Sep","Oct","Nov","Dec"}, 0), 1), Data!L:L, "<" & EDATE(DATE(2025, MATCH(L$56, {"Jan","Feb","Mar","Apr","May","Jun","Jul","Aug","Sep","Oct","Nov","Dec"}, 0), 1), 1)) -> 0 | L16: =SUMIFS(Data!$I:$I, Data!$F:$F, $B72, Data!$C:$C, ">=" & DATE(2025, MATCH(M$56, {"Jan","Feb","Mar","Apr","May","Jun","Jul","Aug","Sep","Oct","Nov","Dec"}, 0), 1), Data!M:M, "<" & EDATE(DATE(2025, MATCH(M$56, {"Jan","Feb","Mar","Apr","May","Jun","Jul","Aug","Sep","Oct","Nov","Dec"}, 0), 1), 1)) -> 0 | M16: =SUMIFS(Data!$I:$I, Data!$F:$F, $B72, Data!$C:$C, ">=" & DATE(2025, MATCH(N$56, {"Jan","Feb","Mar","Apr","May","Jun","Jul","Aug","Sep","Oct","Nov","Dec"}, 0), 1), Data!N:N, "<" & EDATE(DATE(2025, MATCH(N$56, {"Jan","Feb","Mar","Apr","May","Jun","Jul","Aug","Sep","Oct","Nov","Dec"}, 0), 1), 1)) -> 0
A17: Inversión | B17: =SUMIFS(Data!I:I, Data!F:F, $B73, Data!C:C, ">=" & DATE(2025, MATCH(C$56, {"Jan","Feb","Mar","Apr","May","Jun","Jul","Aug","Sep","Oct","Nov","Dec"}, 0), 1), Data!C:C, "<" & EDATE(DATE(2025, MATCH(C$56, {"Jan","Feb","Mar","Apr","May","Jun","Jul","Aug","Sep","Oct","Nov","Dec"}, 0), 1), 1)) -> -300 | C17: =SUMIFS(Data!$I:$I, Data!$F:$F, $B73, Data!$C:$C, ">=" & DATE(2025, MATCH(D$56, {"Jan","Feb","Mar","Apr","May","Jun","Jul","Aug","Sep","Oct","Nov","Dec"}, 0), 1), Data!D:D, "<" & EDATE(DATE(2025, MATCH(D$56, {"Jan","Feb","Mar","Apr","May","Jun","Jul","Aug","Sep","Oct","Nov","Dec"}, 0), 1), 1)) -> -1900 | D17: =SUMIFS(Data!$I:$I, Data!$F:$F, $B73, Data!$C:$C, ">=" & DATE(2025, MATCH(E$56, {"Jan","Feb","Mar","Apr","May","Jun","Jul","Aug","Sep","Oct","Nov","Dec"}, 0), 1), Data!E:E, "<" & EDATE(DATE(2025, MATCH(E$56, {"Jan","Feb","Mar","Apr","May","Jun","Jul","Aug","Sep","Oct","Nov","Dec"}, 0), 1), 1)) -> -1100 | E17: =SUMIFS(Data!$I:$I, Data!$F:$F, $B73, Data!$C:$C, ">=" & DATE(2025, MATCH(F$56, {"Jan","Feb","Mar","Apr","May","Jun","Jul","Aug","Sep","Oct","Nov","Dec"}, 0), 1), Data!F:F, "<" & EDATE(DATE(2025, MATCH(F$56, {"Jan","Feb","Mar","Apr","May","Jun","Jul","Aug","Sep","Oct","Nov","Dec"}, 0), 1), 1)) -> 0 | F17: =SUMIFS(Data!$I:$I, Data!$F:$F, $B73, Data!$C:$C, ">=" & DATE(2025, MATCH(G$56, {"Jan","Feb","Mar","Apr","May","Jun","Jul","Aug","Sep","Oct","Nov","Dec"}, 0), 1), Data!G:G, "<" & EDATE(DATE(2025, MATCH(G$56, {"Jan","Feb","Mar","Apr","May","Jun","Jul","Aug","Sep","Oct","Nov","Dec"}, 0), 1), 1)) -> 0 | G17: =SUMIFS(Data!$I:$I, Data!$F:$F, $B73, Data!$C:$C, ">=" & DATE(2025, MATCH(H$56, {"Jan","Feb","Mar","Apr","May","Jun","Jul","Aug","Sep","Oct","Nov","Dec"}, 0), 1), Data!H:H, "<" & EDATE(DATE(2025, MATCH(H$56, {"Jan","Feb","Mar","Apr","May","Jun","Jul","Aug","Sep","Oct","Nov","Dec"}, 0), 1), 1)) -> 0 | H17: =SUMIFS(Data!$I:$I, Data!$F:$F, $B73, Data!$C:$C, ">=" & DATE(2025, MATCH(I$56, {"Jan","Feb","Mar","Apr","May","Jun","Jul","Aug","Sep","Oct","Nov","Dec"}, 0), 1), Data!I:I, "<" & EDATE(DATE(2025, MATCH(I$56, {"Jan","Feb","Mar","Apr","May","Jun","Jul","Aug","Sep","Oct","Nov","Dec"}, 0), 1), 1)) -> -6150 | I17: =SUMIFS(Data!$I:$I, Data!$F:$F, $B73, Data!$C:$C, ">=" & DATE(2025, MATCH(J$56, {"Jan","Feb","Mar","Apr","May","Jun","Jul","Aug","Sep","Oct","Nov","Dec"}, 0), 1), Data!J:J, "<" & EDATE(DATE(2025, MATCH(J$56, {"Jan","Feb","Mar","Apr","May","Jun","Jul","Aug","Sep","Oct","Nov","Dec"}, 0), 1), 1)) -> 0 | J17: =SUMIFS(Data!$I:$I, Data!$F:$F, $B73, Data!$C:$C, ">=" & DATE(2025, MATCH(K$56, {"Jan","Feb","Mar","Apr","May","Jun","Jul","Aug","Sep","Oct","Nov","Dec"}, 0), 1), Data!K:K, "<" & EDATE(DATE(2025, MATCH(K$56, {"Jan","Feb","Mar","Apr","May","Jun","Jul","Aug","Sep","Oct","Nov","Dec"}, 0), 1), 1)) -> -5300 | K17: =SUMIFS(Data!$I:$I, Data!$F:$F, $B73, Data!$C:$C, ">=" & DATE(2025, MATCH(L$56, {"Jan","Feb","Mar","Apr","May","Jun","Jul","Aug","Sep","Oct","Nov","Dec"}, 0), 1), Data!L:L, "<" & EDATE(DATE(2025, MATCH(L$56, {"Jan","Feb","Mar","Apr","May","Jun","Jul","Aug","Sep","Oct","Nov","Dec"}, 0), 1), 1)) -> 0 | L17: =SUMIFS(Data!$I:$I, Data!$F:$F, $B73, Data!$C:$C, ">=" & DATE(2025, MATCH(M$56, {"Jan","Feb","Mar","Apr","May","Jun","Jul","Aug","Sep","Oct","Nov","Dec"}, 0), 1), Data!M:M, "<" & EDATE(DATE(2025, MATCH(M$56, {"Jan","Feb","Mar","Apr","May","Jun","Jul","Aug","Sep","Oct","Nov","Dec"}, 0), 1), 1)) -> 0 | M17: =SUMIFS(Data!$I:$I, Data!$F:$F, $B73, Data!$C:$C, ">=" & DATE(2025, MATCH(N$56, {"Jan","Feb","Mar","Apr","May","Jun","Jul","Aug","Sep","Oct","Nov","Dec"}, 0), 1), Data!N:N, "<" & EDATE(DATE(2025, MATCH(N$56, {"Jan","Feb","Mar","Apr","May","Jun","Jul","Aug","Sep","Oct","Nov","Dec"}, 0), 1), 1)) -> 0
